###Как используются ключевые слова `try`, `throw`, `catch`. Можно ли по-разному обработать разные исключения, вылетающие из одного и того же блока `try`?

 - Ключевое слово (блок) `try` используется как "оболочка" нам кодом, т.е внутри фигурных скобок после `try` пишется исследуемый на исключения код: 

`try { //our script }`

 - Ключевое слово `throw` используется в качестве механизма вызывающего исключение. Дословно мы бросаем исключение, чтобы, возможно, далее его поймать:

`throw std::exception`

 - Ключевое слово (блок)`catch` используется в качестве обработчика исключения, возникшего в блоке `try`:

``` 
try{  
//our script 
} catch(std::exception& ex){ 
//processing 
}

```
 - Обработать различные исключения из одного блока `try` можно по-разному, т.к пойманное исключение можно делегировать, а можно на него отреагировать:

```
try{  
//our script 
} catch(std::exception& ex){ 
//processing 
} catch(Other_ex& other){ 
//other proccessing 
}

```

### Что можно и что нельзя делать, если вы поймали исключение? Что означает нетранзакционность блока `try`? К каким проблемам это может привести? Как эти проблемы решены в Java и Python?

 - Если поймал исключение, его можно обработать, а можно делегировать, т.е передать в следующий `catch`.

 - Нетранзакционность блока  `try` означает, его свойства прерываться в любой момент (в момент появления исключения). Это может привести к серьезным проблемам: неосвобожденная память, незакрытый файл. ~~Было что-то третье, но я забыл(~~

 - В Java и Python существует блок `finally`, в котором указывается все, что точно должно выполниться, даже если вылетит исключение.